Workbook

Sheet Read me
A1: Auction Retest indicator on FxPro MT5 GOLD, 4 Jan 2021 - 2 Oct 2026 (your 1-minute data): profitable settings per goal, accuracy, TP1-TP4, streaks, recovery rules
A3: HOW TO USE THIS FILE:
A4: 1. Strategy guide: pick your goal (most profit, shortest losing streak, longest winning streak, highest win rate, most trades, every year positive, smoothest, simplest,
A5: one session only) and your timeframe. Click the strategy to jump to its column.
A6: 2. <TF> strategies (M1, M5, M15, H1): one column per strategy. Every indicator input is listed with its exact name; yellow = change it to that value, grey = keep the default.
A7: Below the settings: what to expect - trades, win %, TP1-TP4 reached, R per trade in each half and each year, longest winning and losing streaks, deepest fall, $ results.
A8: 3. All profitable settings: every setting that passed the profit rule, with a filter on each column (e.g. longest losing streak <= 6).
A9: 4. Recovery rules, Rule C split test and Crooks A and B test: money management (loss recovery). The rest of the sheets are the research detail.
A11: DATA: 2,037,975 one-minute bars from your MT5 export; 441 fake 00:00 "daily summary" bars removed. M5 / M15 / H1 were built from M1 on the broker clock (EET, UTC+2 / UTC+3 in summer).
A12: ENGINE: the same signal engine as the TradingView indicator / strategy and the MT5 EA (Python twin, checked trade-for-trade against the EA). VWAP and sessions reset at broker midnight; VWAP weights = tick volume.
A13: COSTS: the spread recorded in the MT5 data at each fill bar, as a share of the stop distance ("after spread"). On M1 / M5 the stop is small, so the spread eats a large part of every trade.
A14: DEFINITIONS: R = result in units of the stop distance. TPk hit = price reached that target after the fill bar and before the stop. Win = closed at the final target.
... A31: best = strategy S1 "Most profit", low-streak = the "Shortest losing streak" strategy) | TP1-TP4 | Settings sweep | Combinations | Exits | Robustness | Hours | Streak math

Sheet Strategy guide
A1: Strategy guide: which settings to use for which goal (FxPro MT5 gold, 2021-2026, after the spread)
A2: Part 1: for each goal and timeframe, the strategy to use (click it for the exact settings on the timeframe sheet). Part 2: every strategy with its key numbers. Every strategy is profitable after spread in 2021-23 and 2024-26 and positive in at least 4 of 6 years. "-" = no profitable setting for that goal.
A4: PART 1 - pick by goal
A5: Goal | B5: M1 | C5: M5 | D5: M15 | E5: H1
A6: Most profit | B6: M1-S1: W/L streak 8/14, +0.057 R, 1.32/day | C6: M5-S1: W/L streak 7/21, +0.087 R, 0.99/day | D6: M15-S1: W/L streak 8/17, +0.134 R, 0.93/day | E6: H1-S1: W/L streak 8/8, +0.337 R, 0.13/day
A7: Shortest losing streak | B7: M1-S2: W/L streak 7/12, +0.052 R, 1.21/day | C7: M5-S2: W/L streak 11/9, +0.045 R, 1.14/day | D7: M15-S2: W/L streak 18/5, +0.066 R, 0.77/day | E7: H1-S2: W/L streak 12/3, +0.176 R, 0.13/day
A8: Shortest losing streak - indicator only | B8: M1-S2: W/L streak 7/12, +0.052 R, 1.21/day | C8: M5-S2: W/L streak 11/9, +0.045 R, 1.14/day | D8: M15-S3: W/L streak 6/8, +0.132 R, 0.76/day | E8: H1-S3: W/L streak 7/6, +0.232 R, 0.15/day
A9: Longest winning streak | B9: M1-S1: W/L streak 8/14, +0.057 R, 1.32/day | C9: M5-S2: W/L streak 11/9, +0.045 R, 1.14/day | D9: M15-S4: W/L streak 22/6, +0.070 R, 0.81/day | E9: H1-S4: W/L streak 18/6, +0.108 R, 0.18/day
A10: Highest win rate | B10: M1-S1: W/L streak 8/14, +0.057 R, 1.32/day | C10: M5-S2: W/L streak 11/9, +0.045 R, 1.14/day | D10: M15-S5: W/L streak 21/5, +0.055 R, 0.93/day | E10: H1-S5: W/L streak 13/4, +0.174 R, 0.13/day
A11: Most trades a day | B11: M1-S3: W/L streak 7/14, +0.044 R, 1.42/day | C11: M5-S3: W/L streak 6/13, +0.072 R, 1.22/day | D11: M15-S6: W/L streak 10/11, +0.062 R, 1.20/day | E11: H1-S6: W/L streak 4/16, +0.119 R, 0.36/day
A12: Every year positive | B12: - | C12: M5-S2: W/L streak 11/9, +0.045 R, 1.14/day | D12: M15-S7: W/L streak 8/17, +0.146 R, 0.93/day | E12: H1-S1: W/L streak 8/8, +0.337 R, 0.13/day
A13: Smoothest | B13: M1-S1: W/L streak 8/14, +0.057 R, 1.32/day | C13: M5-S1: W/L streak 7/21, +0.087 R, 0.99/day | D13: M15-S3: W/L streak 6/8, +0.132 R, 0.76/day | E13: H1-S7: W/L streak 10/7, +0.309 R, 0.14/day
A14: Simplest | B14: M1-S4: W/L streak 8/14, +0.041 R, 1.35/day | C14: M5-S4: W/L streak 8/20, +0.058 R, 1.00/day | D14: M15-S8: W/L streak 6/18, +0.084 R, 0.79/day | E14: H1-S8: W/L streak 5/12, +0.105 R, 0.34/day
A15: Asia session only | B15: - | C15: - | D15: M15-S9: W/L streak 6/21, +0.051 R, 0.48/day | E15: -
A16: London session only | B16: - | C16: - | D16: - | E16: -
... A18: London close session only | B18: M1-S1: W/L streak 8/14, +0.057 R, 1.32/day | C18: - | D18: - | E18: -
A20: PART 2 - every strategy
A21: Strategy | B21: Timeframe | C21: Goal(s) | D21: Works in | E21: Trades per day | F21: Profitable trades % | G21: TP1 reached % | H21: R per trade 2021-23 | I21: R per trade 2024-26 | J21: R per trade 2021-2026 | K21: Years positive | L21: Longest winning streak | M21: Longest losing streak | N21: Deepest fall (R) | O21: Fixed $50: net ($) | P21: Rule C split 3, $500 cap, Start again: net ($) | Q21: ... its deepest fall % | R21: Crooks A, $500 cap, Start again: net ($) | S21: ... its deepest fall % | T21: Settings to change (indicator names)
A22: M1-S1 | B22: M1 | C22: Most profit + Longest winning streak + Highest win rate + Smoothest + London close session only | D22: Indicator, strategy and EA | E22: 1.319 | F22: 0.3662 | G22: 0.6297 | H22: 0.0545 | I22: 0.0601 | J22: 0.0573 | K22: 4 | L22: 8 | M22: 14 | N22: 30.01 | O22: 5441.57 | P22: 17859.4 | Q22: 0.4614 | R22: 15765.65 | S22: 0.1767 | T22: Stop Distance (x ATR) = 4 | Cooldown After Exit (bars) = 8 | Anchor = Month | Trade Only In Kill Zones (Indian time) = On: London Close 19:30-21:30
A23: M1-S2 | B23: M1 | C23: Shortest losing streak + Shortest losing streak - indicator only | D23: Indicator, strategy and EA | E23: 1.213 | F23: 0.3646 | G23: 0.626 | H23: 0.0286 | I23: 0.075 | J23: 0.0516 | K23: 4 | L23: 7 | M23: 12 | N23: 30.73 | O23: 4561.27 | P23: 29940.03 | Q23: 0.4104 | R23: 965.26 | S23: 0.3664 | T23: Stop Distance (x ATR) = 4 | Cooldown After Exit (bars) = 30 | Anchor = Month | Trade Only In Kill Zones (Indian time) = On: London Close 19:30-21:30
A24: M1-S3 | B24: M1 | C24: Most trades a day | D24: Indicator, strategy and EA | E24: 1.422 | F24: 0.3614 | G24: 0.6239 | H24: 0.0632 | I24: 0.0249 | J24: 0.0439 | K24: 4 | L24: 7 | M24: 14 | N24: 34.45 | O24: 4470.32 | P24: 25623.29 | Q24: 0.3857 | R24: 8960.71 | S24: 0.2492 | T24: Min Displacement Range (x ATR) = 0.4 | Stop Distance (x ATR) = 4 | Anchor = Month | Trade Only In Kill Zones (Indian time) = On: London Close 19:30-21:30
A25: M1-S4 | B25: M1 | C25: Simplest | D25: Indicator, strategy and EA | E25: 1.351 | F25: 0.3609 | G25: 0.6261 | H25: 0.0489 | I25: 0.0341 | J25: 0.0415 | K25: 4 | L25: 8 | M25: 14 | N25: 37.97 | O25: 4040.42 | P25: 25252.4 | Q25: 0.4438 | R25: 10595.14 | S25: 0.1987 | T25: Stop Distance (x ATR) = 4 | Anchor = Month | Trade Only In Kill Zones (Indian time) = On: London Close 19:30-21:30
A27: M5-S1 | B27: M5 | C27: Most profit + Smoothest + New York session only | D27: Indicator, strategy and EA | E27: 0.991 | F27: 0.3207 | G27: 0.6291 | H27: 0.0969 | I27: 0.0776 | J27: 0.0872 | K27: 4 | L27: 7 | M27: 21 | N27: 37.22 | O27: 6136.32 | P27: 51480.28 | Q27: 0.3588 | R27: 9244.49 | S27: 0.3077 | T27: Stop Distance (x ATR) = 2.4 | TP4 (R) = 2.5 | Anchor = Month | Entry Price = Market (next bar open) | Skip Choppy Sessions: Max VWAP Crosses Per 100 Bars = On, 8 | Trade Only Between (Time Zone = Asia/Kolkata) = On, 1830-2230
A28: M5-S2 | B28: M5 | C28: Shortest losing streak + Shortest losing streak - indicator only + Longest winning streak + Highest win rate + Every year positive | D28: Indicator, strategy and EA | E28: 1.139 | F28: 0.5236 | G28: 0.6277 | H28: 0.0465 | I28: 0.0434 | J28: 0.045 | K28: 6 | L28: 11 | M28: 9 | N28: 25.77 | O28: 3667.19 | P28: 24417.33 | Q28: 0.341 | R28: 2116.38 | S28: 0.1925 | T28: Stop Distance (x ATR) = 2.4 | Anchor = Month | Entry Price = Market (next bar open) | When TP2 Hits, Move Stop To (R) = On, 0.6 R | Skip Choppy Sessions: Max VWAP Crosses Per 100 Bars = On, 8 | Trade Only Between (Time Zone = Asia/Kolkata) = On, 1830-2230
A29: M5-S3 | B29: M5 | C29: Most trades a day | D29: Indicator, strategy and EA | E29: 1.215 | F29: 0.369 | G29: 0.6299 | H29: 0.066 | I29: 0.0786 | J29: 0.0723 | K29: 4 | L29: 6 | M29: 13 | N29: 37.95 | O29: 6275.5 | P29: 38465.04 | Q29: 0.4522 | R29: 14021.94 | S29: 0.1534 | T29: Momentum Lookback (bars) = 5 | Stop Distance (x ATR) = 2.4 | Anchor = Month | Entry Price = Market (next bar open) | Skip Choppy Sessions: Max VWAP Crosses Per 100 Bars = On, 8 | Trade Only Between (Time Zone = Asia/Kolkata) = On, 1830-2230
A30: M5-S4 | B30: M5 | C30: Simplest | D30: Indicator, strategy and EA | E30: 1.002 | F30: 0.3683 | G30: 0.6263 | H30: 0.0696 | I30: 0.045 | J30: 0.0578 | K30: 4 | L30: 8 | M30: 20 | N30: 44.7 | O30: 4134.19 | P30: 5171.53 | Q30: 0.4951 | R30: 5156.73 | S30: 0.2282 | T30: Anchor = Month | Entry Price = Market (next bar open) | Skip Choppy Sessions: Max VWAP Crosses Per 100 Bars = On, 8 | Skip When The 1h EMA20 Moved More Than ... ATR In 3 Hours = On, 1.4 | Trade Only Between (Time Zone = Asia/Kolkata) = On, 1830-2230
A32: M15-S1 | B32: M15 | C32: Most profit | D32: Indicator, strategy and EA | E32: 0.935 | F32: 0.4539 | G32: 0.6628 | H32: 0.1353 | I32: 0.1324 | J32: 0.1338 | K32: 6 | L32: 8 | M32: 17 | N32: 23.23 | O32: 9076.9 | P32: 67852.71 | Q32: 0.3608 | R32: 12348.06 | S32: 0.1619 | T32: Stop Distance (x ATR) = 4 | Half Stop (x ATR) = 1.2 | When TP3 Hits, Move Stop To (R) = On, 1 R
A33: M15-S2 | B33: M15 | C33: Shortest losing streak | D33: Strategy and EA only (partial close) | E33: 0.766 | F33: 0.6614 | G33: 0.6614 | H33: 0.0648 | I33: 0.0682 | J33: 0.0664 | K33: 6 | L33: 18 | M33: 5 | N33: 22.61 | O33: 3704.09 | P33: 15152.96 | Q33: 0.3727 | R33: 3169.3 | S33: 0.1444 | T33: Min CMO (clean move) = 30 | Stop Distance (x ATR) = 4 | Half Stop (x ATR) = 1.2 | When TP3 Hits, Move Stop To (R) = On, 1 R | Skip When The 1h EMA20 Moved More Than ... ATR In 3 Hours = On, 1.2 | Close % At TP1 = 70
A34: M15-S3 | B34: M15 | C34: Shortest losing streak - indicator only + Smoothest | D34: Indicator, strategy and EA | E34: 0.76 | F34: 0.4517 | G34: 0.6537 | H34: 0.1343 | I34: 0.1294 | J34: 0.1319 | K34: 6 | L34: 6 | M34: 8 | N34: 14.36 | O34: 7274.17 | P34: 47681.14 | Q34: 0.2564 | R34: 11592.75 | S34: 0.0624 | T34: Stop Distance (x ATR) = 4 | Half Stop (x ATR) = 1.2 | VWAP Slope Bars = 0 | When TP3 Hits, Move Stop To (R) = On, 1 R | Skip When The 1h EMA20 Moved More Than ... ATR In 3 Hours = On, 1.2
A35: M15-S4 | B35: M15 | C35: Longest winning streak | D35: Strategy and EA only (partial close) | E35: 0.813 | F35: 0.6628 | G35: 0.6628 | H35: 0.0765 | I35: 0.0639 | J35: 0.0702 | K35: 6 | L35: 22 | M35: 6 | N35: 24.32 | O35: 4150.61 | P35: 25426.18 | Q35: 0.3976 | R35: 4529.84 | S35: 0.1008 | T35: Stop Distance (x ATR) = 4 | Half Stop (x ATR) = 1.2 | When TP3 Hits, Move Stop To (R) = On, 1 R | Skip Choppy Sessions: Max VWAP Crosses Per 100 Bars = On, 16 | Close % At TP1 = 70
... A49: H1-S8 | B49: H1 | C49: Simplest | D49: Indicator, strategy and EA | E49: 0.335 | F49: 0.3755 | G49: 0.6104 | H49: 0.097 | I49: 0.1129 | J49: 0.1051 | K49: 4 | L49: 5 | M49: 12 | N49: 23.94 | O49: 2557.3 | P49: 1289.09 | Q49: 0.2886 | R49: 3966.05 | S49: 0.1544 | T49: Anchor = Month | Don't Chase: Skip Signals Beyond ... sigma From VWAP = On, 2.2

Sheet M1 strategies
A1: M1: profitable settings for each scenario - what to set in the indicator and what to expect
A2: Pick the column for your goal and read down. Yellow cells = change this input to the value shown; grey = leave the default. All results are 2021-2026 on FxPro gold after the spread, and every setting here was profitable in both 2021-23 and 2024-26 with at least 4 of 6 years positive. Expect live results to be weaker.
A4: Group | B4: Input (exactly as in the indicator) | C4: MT5 EA input | D4: Default | E4: M1-S1 | F4: M1-S2 | G4: M1-S3 | H4: M1-S4
A5: WHEN TO USE IT
B6: Scenario | E6: Most profit + Longest winning streak + Highest win rate + Smoothest + London close session only | F6: Shortest losing streak + Shortest losing streak - indicator only | G6: Most trades a day | H6: Simplest
B7: Use it when | E7: Best R per trade after spread in both halves (ranked by the weaker half); the main recommendation. The most wins in a row. The largest share of profitable trades. The best profit for the deepest fall from a peak (total R / max drawdown in R), among the 25 strongest settings. Trades only in the London close session (Indian time); for traders who can only watch that session. | F7: The fewest losses in a row, keeping a fair profit. May use a partial close (strategy / EA only). As above, without a partial close, so the indicator shows the same trades and results. | G7: The most trades while still profitable in both halves. | H7: The fewest settings to change.
B8: Works in | E8: Indicator, strategy and EA | F8: Indicator, strategy and EA | G8: Indicator, strategy and EA | H8: Indicator, strategy and EA
A9: SETTINGS - change the yellow cells, leave the rest at the default
A10: SIGNAL MODEL | B10: Structure Lookback (bars) | C10: InpStructLen | D10: 10 | E10: 10 | F10: 10 | G10: 10 | H10: 10
B11: Signal Break Lookback (bars) | C11: InpBrkLen | D11: 6 | E11: 6 | F11: 6 | G11: 6 | H11: 6
B12: Entry Level Lookback (bars) | C12: InpEntryLen | D12: 6 | E12: 6 | F12: 6 | G12: 6 | H12: 6
B13: Retest Window (bars) | C13: InpRetestBars | D13: 5 | E13: 5 | F13: 5 | G13: 5 | H13: 5
B14: Min Displacement Range (x ATR) | C14: InpDispAtr | D14: 0.8 | E14: 0.8 | F14: 0.8 | G14: 0.4 | H14: 0.8
B15: Min Displacement Body (% of range) | C15: InpBodyPct | D15: 55 | E15: 55 | F15: 55 | G15: 55 | H15: 55
B16: Max Close Distance From Extreme (% of range) | C16: InpClosePct | D16: 25 | E16: 25 | F16: 25 | G16: 25 | H16: 25
B17: Momentum Lookback (bars) | C17: InpMomLen | D17: 10 | E17: 10 | F17: 10 | G17: 10 | H17: 10
B18: Min (x ATR) [same line as Momentum Lookback] | C18: InpMomAtr | D18: 0.85 | E18: 0.85 | F18: 0.85 | G18: 0.85 | H18: 0.85
B19: Min CMO (clean move) | C19: InpCmoMin | D19: 20 | E19: 20 | F19: 20 | G19: 20 | H19: 20
B20: Same-Direction Re-arm | C20: InpRearm | D20: Keep first | E20: Keep first | F20: Keep first | G20: Keep first | H20: Keep first
B21: Stop Mode | C21: InpStopMode | D21: ATR Model | E21: ATR Model | F21: ATR Model | G21: ATR Model | H21: ATR Model
B22: Stop Distance (x ATR) | C22: InpStopAtr | D22: 1.8 | E22: 4 | F22: 4 | G22: 4 | H22: 4
... B46: Shorts | C46: InpAllowShort | D46: On | E46: On | F46: On | G46: On | H46: On
A47: VWAP | B47: Anchor | C47: InpVwapAnchor | D47: Session | E47: Month | F47: Month | G47: Month | H47: Month
B48: Source | C48: InpVwapSrc | D48: hlc3 | E48: hlc3 | F48: hlc3 | G48: hlc3 | H48: hlc3
A49: ENTRY PRICE | B49: Entry Price | C49: InpEntryMode | D49: Model (body mid or 6-bar level) | E49: Model (body mid or 6-bar level) | F49: Model (body mid or 6-bar level) | G49: Model (body mid or 6-bar level) | H49: Model (body mid or 6-bar level)
B50: Custom % (0 = close, 50 = mid, 100 = low/high) | C50: InpEntryPct | D50: 50 | E50: 50 | F50: 50 | G50: 50 | H50: 50
A51: TARGETS, EXIT AND STOP MOVES | B51: TP1 | C51: InpTp1R | D51: 0.6 | E51: 0.6 | F51: 0.6 | G51: 0.6 | H51: 0.6
B52: TP2 | C52: InpTp2R | D52: 1 | E52: 1 | F52: 1 | G52: 1 | H52: 1
B53: TP3 | C53: InpTp3R | D53: 1.5 | E53: 1.5 | F53: 1.5 | G53: 1.5 | H53: 1.5
B54: TP4 | C54: InpTp4R | D54: 2 | E54: 2 | F54: 2 | G54: 2 | H54: 2
B55: Final Exit At | C55: InpExitAt | D55: TP4 | E55: TP4 | F55: TP4 | G55: TP4 | H55: TP4
B56: When TP1 Hits, Move Stop To (R) [tick box] | C56: InpMv1On | D56: Off | E56: Off | F56: Off | G56: Off | H56: Off
B57: ... value (R) [same line] | C57: InpMv1R | D57: 0 | E57: 0 | F57: 0 | G57: 0 | H57: 0
B58: When TP2 Hits, Move Stop To (R) [tick box] | C58: InpMv2On | D58: Off | E58: Off | F58: Off | G58: Off | H58: Off
B59: ... value (R) [same line] | C59: InpMv2R | D59: 0.6 | E59: 0.6 | F59: 0.6 | G59: 0.6 | H59: 0.6
B60: When TP3 Hits, Move Stop To (R) [tick box] | C60: InpMv3On | D60: Off | E60: Off | F60: Off | G60: Off | H60: Off
B61: ... value (R) [same line] | C61: InpMv3R | D61: 1 | E61: 1 | F61: 1 | G61: 1 | H61: 1
A62: ACCURACY FILTERS | B62: Don't Chase: Skip Signals Beyond [tick box] | C62: InpNoChase | D62: Off | E62: Off | F62: Off | G62: Off | H62: Off
B63: σ From VWAP [same line] | C63: InpNoChaseSig | D63: 2.4 | E63: 2.4 | F63: 2.4 | G63: 2.4 | H63: 2.4
B64: After A Loss, No Same-Direction Trade Until A Win | C64: InpLossBlock | D64: Off | E64: Off | F64: Off | G64: Off | H64: Off
...

Sheet M5 strategies
A1: M5: profitable settings for each scenario - what to set in the indicator and what to expect
A2: Pick the column for your goal and read down. Yellow cells = change this input to the value shown; grey = leave the default. All results are 2021-2026 on FxPro gold after the spread, and every setting here was profitable in both 2021-23 and 2024-26 with at least 4 of 6 years positive. Expect live results to be weaker.
A4: Group | B4: Input (exactly as in the indicator) | C4: MT5 EA input | D4: Default | E4: M5-S1 | F4: M5-S2 | G4: M5-S3 | H4: M5-S4
A5: WHEN TO USE IT
B6: Scenario | E6: Most profit + Smoothest + New York session only | F6: Shortest losing streak + Shortest losing streak - indicator only + Longest winning streak + Highest win rate + Every year positive | G6: Most trades a day | H6: Simplest
B7: Use it when | E7: Best R per trade after spread in both halves (ranked by the weaker half); the main recommendation. The best profit for the deepest fall from a peak (total R / max drawdown in R), among the 25 strongest settings. Trades only in the New York session (Indian time); for traders who can only watch that session. | F7: The fewest losses in a row, keeping a fair profit. May use a partial close (strategy / EA only). As above, without a partial close, so the indicator shows the same trades and results. The most wins in a row. The largest share of profitable trades. Profitable in all 6 years (2021-2026), best score. | G7: The most trades while still profitable in both halves. | H7: The fewest settings to change.
B8: Works in | E8: Indicator, strategy and EA | F8: Indicator, strategy and EA | G8: Indicator, strategy and EA | H8: Indicator, strategy and EA
A9: SETTINGS - change the yellow cells, leave the rest at the default
A10: SIGNAL MODEL | B10: Structure Lookback (bars) | C10: InpStructLen | D10: 10 | E10: 10 | F10: 10 | G10: 10 | H10: 10
B11: Signal Break Lookback (bars) | C11: InpBrkLen | D11: 6 | E11: 6 | F11: 6 | G11: 6 | H11: 6
B12: Entry Level Lookback (bars) | C12: InpEntryLen | D12: 6 | E12: 6 | F12: 6 | G12: 6 | H12: 6
B13: Retest Window (bars) | C13: InpRetestBars | D13: 5 | E13: 5 | F13: 5 | G13: 5 | H13: 5
B14: Min Displacement Range (x ATR) | C14: InpDispAtr | D14: 0.8 | E14: 0.8 | F14: 0.8 | G14: 0.8 | H14: 0.8
B15: Min Displacement Body (% of range) | C15: InpBodyPct | D15: 55 | E15: 55 | F15: 55 | G15: 55 | H15: 55
B16: Max Close Distance From Extreme (% of range) | C16: InpClosePct | D16: 25 | E16: 25 | F16: 25 | G16: 25 | H16: 25
B17: Momentum Lookback (bars) | C17: InpMomLen | D17: 10 | E17: 10 | F17: 10 | G17: 5 | H17: 10
B18: Min (x ATR) [same line as Momentum Lookback] | C18: InpMomAtr | D18: 0.85 | E18: 0.85 | F18: 0.85 | G18: 0.85 | H18: 0.85
B19: Min CMO (clean move) | C19: InpCmoMin | D19: 20 | E19: 20 | F19: 20 | G19: 20 | H19: 20
B20: Same-Direction Re-arm | C20: InpRearm | D20: Keep first | E20: Keep first | F20: Keep first | G20: Keep first | H20: Keep first
B21: Stop Mode | C21: InpStopMode | D21: ATR Model | E21: ATR Model | F21: ATR Model | G21: ATR Model | H21: ATR Model
B22: Stop Distance (x ATR) | C22: InpStopAtr | D22: 1.8 | E22: 2.4 | F22: 2.4 | G22: 2.4 | H22: 1.8
... B46: Shorts | C46: InpAllowShort | D46: On | E46: On | F46: On | G46: On | H46: On
A47: VWAP | B47: Anchor | C47: InpVwapAnchor | D47: Session | E47: Month | F47: Month | G47: Month | H47: Month
B48: Source | C48: InpVwapSrc | D48: hlc3 | E48: hlc3 | F48: hlc3 | G48: hlc3 | H48: hlc3
A49: ENTRY PRICE | B49: Entry Price | C49: InpEntryMode | D49: Model (body mid or 6-bar level) | E49: Market (next bar open) | F49: Market (next bar open) | G49: Market (next bar open) | H49: Market (next bar open)
B50: Custom % (0 = close, 50 = mid, 100 = low/high) | C50: InpEntryPct | D50: 50 | E50: 50 | F50: 50 | G50: 50 | H50: 50
A51: TARGETS, EXIT AND STOP MOVES | B51: TP1 | C51: InpTp1R | D51: 0.6 | E51: 0.6 | F51: 0.6 | G51: 0.6 | H51: 0.6
B52: TP2 | C52: InpTp2R | D52: 1 | E52: 1 | F52: 1 | G52: 1 | H52: 1
B53: TP3 | C53: InpTp3R | D53: 1.5 | E53: 1.5 | F53: 1.5 | G53: 1.5 | H53: 1.5
B54: TP4 | C54: InpTp4R | D54: 2 | E54: 2.5 | F54: 2 | G54: 2 | H54: 2
B55: Final Exit At | C55: InpExitAt | D55: TP4 | E55: TP4 | F55: TP4 | G55: TP4 | H55: TP4
B56: When TP1 Hits, Move Stop To (R) [tick box] | C56: InpMv1On | D56: Off | E56: Off | F56: Off | G56: Off | H56: Off
B57: ... value (R) [same line] | C57: InpMv1R | D57: 0 | E57: 0 | F57: 0 | G57: 0 | H57: 0
B58: When TP2 Hits, Move Stop To (R) [tick box] | C58: InpMv2On | D58: Off | E58: Off | F58: On | G58: Off | H58: Off
B59: ... value (R) [same line] | C59: InpMv2R | D59: 0.6 | E59: 0.6 | F59: 0.6 | G59: 0.6 | H59: 0.6
B60: When TP3 Hits, Move Stop To (R) [tick box] | C60: InpMv3On | D60: Off | E60: Off | F60: Off | G60: Off | H60: Off
B61: ... value (R) [same line] | C61: InpMv3R | D61: 1 | E61: 1 | F61: 1 | G61: 1 | H61: 1
A62: ACCURACY FILTERS | B62: Don't Chase: Skip Signals Beyond [tick box] | C62: InpNoChase | D62: Off | E62: Off | F62: Off | G62: Off | H62: Off
B63: σ From VWAP [same line] | C63: InpNoChaseSig | D63: 2.4 | E63: 2.4 | F63: 2.4 | G63: 2.4 | H63: 2.4
B64: After A Loss, No Same-Direction Trade Until A Win | C64: InpLossBlock | D64: Off | E64: Off | F64: Off | G64: Off | H64: Off
...

Sheet M15 strategies
A1: M15: profitable settings for each scenario - what to set in the indicator and what to expect
A2: Pick the column for your goal and read down. Yellow cells = change this input to the value shown; grey = leave the default. All results are 2021-2026 on FxPro gold after the spread, and every setting here was profitable in both 2021-23 and 2024-26 with at least 4 of 6 years positive. Expect live results to be weaker.
A4: Group | B4: Input (exactly as in the indicator) | C4: MT5 EA input | D4: Default | E4: M15-S1 | F4: M15-S2 | G4: M15-S3 | H4: M15-S4 | I4: M15-S5 | J4: M15-S6 | K4: M15-S7 | L4: M15-S8 | M4: M15-S9
A5: WHEN TO USE IT
B6: Scenario | E6: Most profit | F6: Shortest losing streak | G6: Shortest losing streak - indicator only + Smoothest | H6: Longest winning streak | I6: Highest win rate | J6: Most trades a day | K6: Every year positive | L6: Simplest | M6: Asia session only
B7: Use it when | E7: Best R per trade after spread in both halves (ranked by the weaker half); the main recommendation. | F7: The fewest losses in a row, keeping a fair profit. May use a partial close (strategy / EA only). | G7: As above, without a partial close, so the indicator shows the same trades and results. The best profit for the deepest fall from a peak (total R / max drawdown in R), among the 25 strongest settings. | H7: The most wins in a row. | I7: The largest share of profitable trades. | J7: The most trades while still profitable in both halves. | K7: Profitable in all 6 years (2021-2026), best score. | L7: The fewest settings to change. | M7: Trades only in the Asia session (Indian time); for traders who can only watch that session.
B8: Works in | E8: Indicator, strategy and EA | F8: Strategy and EA only (partial close) | G8: Indicator, strategy and EA | H8: Strategy and EA only (partial close) | I8: Strategy and EA only (partial close) | J8: Indicator, strategy and EA | K8: Indicator, strategy and EA | L8: Indicator, strategy and EA | M8: Indicator, strategy and EA
A9: SETTINGS - change the yellow cells, leave the rest at the default
A10: SIGNAL MODEL | B10: Structure Lookback (bars) | C10: InpStructLen | D10: 10 | E10: 10 | F10: 10 | G10: 10 | H10: 10 | I10: 10 | J10: 10 | K10: 10 | L10: 10 | M10: 10
B11: Signal Break Lookback (bars) | C11: InpBrkLen | D11: 6 | E11: 6 | F11: 6 | G11: 6 | H11: 6 | I11: 6 | J11: 6 | K11: 8 | L11: 6 | M11: 6
B12: Entry Level Lookback (bars) | C12: InpEntryLen | D12: 6 | E12: 6 | F12: 6 | G12: 6 | H12: 6 | I12: 6 | J12: 6 | K12: 6 | L12: 6 | M12: 8
B13: Retest Window (bars) | C13: InpRetestBars | D13: 5 | E13: 5 | F13: 5 | G13: 5 | H13: 5 | I13: 5 | J13: 5 | K13: 5 | L13: 5 | M13: 5
B14: Min Displacement Range (x ATR) | C14: InpDispAtr | D14: 0.8 | E14: 0.8 | F14: 0.8 | G14: 0.8 | H14: 0.8 | I14: 0.8 | J14: 0.8 | K14: 0.8 | L14: 0.8 | M14: 0.8
B15: Min Displacement Body (% of range) | C15: InpBodyPct | D15: 55 | E15: 55 | F15: 55 | G15: 55 | H15: 55 | I15: 55 | J15: 55 | K15: 55 | L15: 55 | M15: 55
B16: Max Close Distance From Extreme (% of range) | C16: InpClosePct | D16: 25 | E16: 25 | F16: 25 | G16: 25 | H16: 25 | I16: 25 | J16: 25 | K16: 25 | L16: 25 | M16: 25
B17: Momentum Lookback (bars) | C17: InpMomLen | D17: 10 | E17: 10 | F17: 10 | G17: 10 | H17: 10 | I17: 10 | J17: 10 | K17: 10 | L17: 10 | M17: 10
B18: Min (x ATR) [same line as Momentum Lookback] | C18: InpMomAtr | D18: 0.85 | E18: 0.85 | F18: 0.85 | G18: 0.85 | H18: 0.85 | I18: 0.85 | J18: 0.85 | K18: 0.85 | L18: 0.85 | M18: 0.85
B19: Min CMO (clean move) | C19: InpCmoMin | D19: 20 | E19: 20 | F19: 30 | G19: 20 | H19: 20 | I19: 20 | J19: 20 | K19: 20 | L19: 20 | M19: 20
B20: Same-Direction Re-arm | C20: InpRearm | D20: Keep first | E20: Keep first | F20: Keep first | G20: Keep first | H20: Keep first | I20: Keep first | J20: Keep first | K20: Keep first | L20: Keep first | M20: Keep first
B21: Stop Mode | C21: InpStopMode | D21: ATR Model | E21: ATR Model | F21: ATR Model | G21: ATR Model | H21: ATR Model | I21: ATR Model | J21: ATR Model | K21: ATR Model | L21: ATR Model | M21: ATR Model
B22: Stop Distance (x ATR) | C22: InpStopAtr | D22: 1.8 | E22: 4 | F22: 4 | G22: 4 | H22: 4 | I22: 4 | J22: 4 | K22: 4 | L22: 4 | M22: 4
... B46: Shorts | C46: InpAllowShort | D46: On | E46: On | F46: On | G46: On | H46: On | I46: On | J46: On | K46: On | L46: On | M46: On
A47: VWAP | B47: Anchor | C47: InpVwapAnchor | D47: Session | E47: Session | F47: Session | G47: Session | H47: Session | I47: Session | J47: Session | K47: Session | L47: Session | M47: Session
B48: Source | C48: InpVwapSrc | D48: hlc3 | E48: hlc3 | F48: hlc3 | G48: hlc3 | H48: hlc3 | I48: hlc3 | J48: hlc3 | K48: hlc3 | L48: hlc3 | M48: hlc3
A49: ENTRY PRICE | B49: Entry Price | C49: InpEntryMode | D49: Model (body mid or 6-bar level) | E49: Model (body mid or 6-bar level) | F49: Model (body mid or 6-bar level) | G49: Model (body mid or 6-bar level) | H49: Model (body mid or 6-bar level) | I49: Model (body mid or 6-bar level) | J49: Model (body mid or 6-bar level) | K49: Model (body mid or 6-bar level) | L49: Model (body mid or 6-bar level) | M49: Model (body mid or 6-bar level)
B50: Custom % (0 = close, 50 = mid, 100 = low/high) | C50: InpEntryPct | D50: 50 | E50: 50 | F50: 50 | G50: 50 | H50: 50 | I50: 50 | J50: 50 | K50: 50 | L50: 50 | M50: 50
A51: TARGETS, EXIT AND STOP MOVES | B51: TP1 | C51: InpTp1R | D51: 0.6 | E51: 0.6 | F51: 0.6 | G51: 0.6 | H51: 0.6 | I51: 0.5 | J51: 0.6 | K51: 0.6 | L51: 0.6 | M51: 0.6
B52: TP2 | C52: InpTp2R | D52: 1 | E52: 1 | F52: 1 | G52: 1 | H52: 1 | I52: 1 | J52: 1 | K52: 1 | L52: 1 | M52: 1
B53: TP3 | C53: InpTp3R | D53: 1.5 | E53: 1.5 | F53: 1.5 | G53: 1.5 | H53: 1.5 | I53: 1.5 | J53: 1.5 | K53: 1.5 | L53: 1.5 | M53: 1.5
B54: TP4 | C54: InpTp4R | D54: 2 | E54: 2 | F54: 2 | G54: 2 | H54: 2 | I54: 2 | J54: 2 | K54: 2 | L54: 2 | M54: 2
B55: Final Exit At | C55: InpExitAt | D55: TP4 | E55: TP4 | F55: TP4 | G55: TP4 | H55: TP4 | I55: TP4 | J55: TP4 | K55: TP4 | L55: TP4 | M55: TP4
B56: When TP1 Hits, Move Stop To (R) [tick box] | C56: InpMv1On | D56: Off | E56: Off | F56: Off | G56: Off | H56: Off | I56: Off | J56: Off | K56: Off | L56: Off | M56: Off
B57: ... value (R) [same line] | C57: InpMv1R | D57: 0 | E57: 0 | F57: 0 | G57: 0 | H57: 0 | I57: 0 | J57: 0 | K57: 0 | L57: 0 | M57: 0
B58: When TP2 Hits, Move Stop To (R) [tick box] | C58: InpMv2On | D58: Off | E58: Off | F58: Off | G58: Off | H58: Off | I58: Off | J58: On | K58: Off | L58: Off | M58: Off
B59: ... value (R) [same line] | C59: InpMv2R | D59: 0.6 | E59: 0.6 | F59: 0.6 | G59: 0.6 | H59: 0.6 | I59: 0.6 | J59: 0.6 | K59: 0.6 | L59: 0.6 | M59: 0.6
B60: When TP3 Hits, Move Stop To (R) [tick box] | C60: InpMv3On | D60: Off | E60: On | F60: On | G60: On | H60: On | I60: On | J60: On | K60: On | L60: Off | M60: On
B61: ... value (R) [same line] | C61: InpMv3R | D61: 1 | E61: 1 | F61: 1 | G61: 1 | H61: 1 | I61: 1 | J61: 1 | K61: 1 | L61: 1 | M61: 1
A62: ACCURACY FILTERS | B62: Don't Chase: Skip Signals Beyond [tick box] | C62: InpNoChase | D62: Off | E62: Off | F62: Off | G62: Off | H62: Off | I62: Off | J62: Off | K62: Off | L62: Off | M62: Off
B63: σ From VWAP [same line] | C63: InpNoChaseSig | D63: 2.4 | E63: 2.4 | F63: 2.4 | G63: 2.4 | H63: 2.4 | I63: 2.4 | J63: 2.4 | K63: 2.4 | L63: 2.4 | M63: 2.4
B64: After A Loss, No Same-Direction Trade Until A Win | C64: InpLossBlock | D64: Off | E64: Off | F64: Off | G64: Off | H64: Off | I64: Off | J64: Off | K64: Off | L64: Off | M64: Off
...

Sheet H1 strategies
A1: H1: profitable settings for each scenario - what to set in the indicator and what to expect
A2: Pick the column for your goal and read down. Yellow cells = change this input to the value shown; grey = leave the default. All results are 2021-2026 on FxPro gold after the spread, and every setting here was profitable in both 2021-23 and 2024-26 with at least 4 of 6 years positive. Expect live results to be weaker.
A4: Group | B4: Input (exactly as in the indicator) | C4: MT5 EA input | D4: Default | E4: H1-S1 | F4: H1-S2 | G4: H1-S3 | H4: H1-S4 | I4: H1-S5 | J4: H1-S6 | K4: H1-S7 | L4: H1-S8
A5: WHEN TO USE IT
B6: Scenario | E6: Most profit + Every year positive | F6: Shortest losing streak | G6: Shortest losing streak - indicator only | H6: Longest winning streak | I6: Highest win rate | J6: Most trades a day | K6: Smoothest | L6: Simplest
B7: Use it when | E7: Best R per trade after spread in both halves (ranked by the weaker half); the main recommendation. Profitable in all 6 years (2021-2026), best score. | F7: The fewest losses in a row, keeping a fair profit. May use a partial close (strategy / EA only). | G7: As above, without a partial close, so the indicator shows the same trades and results. | H7: The most wins in a row. | I7: The largest share of profitable trades. | J7: The most trades while still profitable in both halves. | K7: The best profit for the deepest fall from a peak (total R / max drawdown in R), among the 25 strongest settings. | L7: The fewest settings to change.
B8: Works in | E8: Indicator, strategy and EA | F8: Strategy and EA only (partial close) | G8: Indicator, strategy and EA | H8: Strategy and EA only (partial close) | I8: Strategy and EA only (partial close) | J8: Indicator, strategy and EA | K8: Indicator, strategy and EA | L8: Indicator, strategy and EA
A9: SETTINGS - change the yellow cells, leave the rest at the default
A10: SIGNAL MODEL | B10: Structure Lookback (bars) | C10: InpStructLen | D10: 10 | E10: 10 | F10: 20 | G10: 10 | H10: 20 | I10: 10 | J10: 20 | K10: 20 | L10: 10
B11: Signal Break Lookback (bars) | C11: InpBrkLen | D11: 6 | E11: 6 | F11: 6 | G11: 6 | H11: 6 | I11: 6 | J11: 6 | K11: 6 | L11: 6
B12: Entry Level Lookback (bars) | C12: InpEntryLen | D12: 6 | E12: 6 | F12: 6 | G12: 6 | H12: 6 | I12: 6 | J12: 6 | K12: 6 | L12: 6
B13: Retest Window (bars) | C13: InpRetestBars | D13: 5 | E13: 5 | F13: 5 | G13: 5 | H13: 5 | I13: 5 | J13: 5 | K13: 5 | L13: 5
B14: Min Displacement Range (x ATR) | C14: InpDispAtr | D14: 0.8 | E14: 0.65 | F14: 0.8 | G14: 0.8 | H14: 0.5 | I14: 0.8 | J14: 0.5 | K14: 0.8 | L14: 0.8
B15: Min Displacement Body (% of range) | C15: InpBodyPct | D15: 55 | E15: 55 | F15: 55 | G15: 60 | H15: 55 | I15: 55 | J15: 45 | K15: 55 | L15: 55
B16: Max Close Distance From Extreme (% of range) | C16: InpClosePct | D16: 25 | E16: 25 | F16: 25 | G16: 25 | H16: 25 | I16: 25 | J16: 25 | K16: 25 | L16: 25
B17: Momentum Lookback (bars) | C17: InpMomLen | D17: 10 | E17: 5 | F17: 10 | G17: 10 | H17: 5 | I17: 10 | J17: 10 | K17: 10 | L17: 10
B18: Min (x ATR) [same line as Momentum Lookback] | C18: InpMomAtr | D18: 0.85 | E18: 0.85 | F18: 0.85 | G18: 0.85 | H18: 0.85 | I18: 0.85 | J18: 0.85 | K18: 0.85 | L18: 0.85
B19: Min CMO (clean move) | C19: InpCmoMin | D19: 20 | E19: 20 | F19: 20 | G19: 20 | H19: 20 | I19: 20 | J19: 20 | K19: 20 | L19: 20
B20: Same-Direction Re-arm | C20: InpRearm | D20: Keep first | E20: Keep first | F20: Keep first | G20: Keep first | H20: Keep first | I20: Keep first | J20: Keep first | K20: Keep first | L20: Keep first
B21: Stop Mode | C21: InpStopMode | D21: ATR Model | E21: ATR Model | F21: ATR Model | G21: ATR Model | H21: ATR Model | I21: ATR Model | J21: ATR Model | K21: ATR Model | L21: ATR Model
B22: Stop Distance (x ATR) | C22: InpStopAtr | D22: 1.8 | E22: 2.4 | F22: 2.2 | G22: 2.2 | H22: 2.2 | I22: 2.2 | J22: 2.2 | K22: 2.2 | L22: 1.8
... B46: Shorts | C46: InpAllowShort | D46: On | E46: On | F46: On | G46: On | H46: On | I46: On | J46: On | K46: On | L46: On
A47: VWAP | B47: Anchor | C47: InpVwapAnchor | D47: Session | E47: Session | F47: Month | G47: Session | H47: Month | I47: Month | J47: Month | K47: Month | L47: Month
B48: Source | C48: InpVwapSrc | D48: hlc3 | E48: hlc3 | F48: hlc3 | G48: hlc3 | H48: hlc3 | I48: hlc3 | J48: hlc3 | K48: hlc3 | L48: hlc3
A49: ENTRY PRICE | B49: Entry Price | C49: InpEntryMode | D49: Model (body mid or 6-bar level) | E49: Model (body mid or 6-bar level) | F49: Model (body mid or 6-bar level) | G49: Model (body mid or 6-bar level) | H49: Model (body mid or 6-bar level) | I49: Model (body mid or 6-bar level) | J49: Model (body mid or 6-bar level) | K49: Model (body mid or 6-bar level) | L49: Model (body mid or 6-bar level)
B50: Custom % (0 = close, 50 = mid, 100 = low/high) | C50: InpEntryPct | D50: 50 | E50: 50 | F50: 50 | G50: 50 | H50: 50 | I50: 50 | J50: 50 | K50: 50 | L50: 50
A51: TARGETS, EXIT AND STOP MOVES | B51: TP1 | C51: InpTp1R | D51: 0.6 | E51: 0.6 | F51: 0.6 | G51: 0.6 | H51: 0.6 | I51: 0.6 | J51: 0.6 | K51: 0.6 | L51: 0.6
B52: TP2 | C52: InpTp2R | D52: 1 | E52: 1 | F52: 1 | G52: 1 | H52: 1 | I52: 1 | J52: 1 | K52: 1 | L52: 1
B53: TP3 | C53: InpTp3R | D53: 1.5 | E53: 1.5 | F53: 1.5 | G53: 1.5 | H53: 1.5 | I53: 1.5 | J53: 1.5 | K53: 1.5 | L53: 1.5
B54: TP4 | C54: InpTp4R | D54: 2 | E54: 2 | F54: 2 | G54: 2 | H54: 2 | I54: 2 | J54: 3 | K54: 2 | L54: 2
B55: Final Exit At | C55: InpExitAt | D55: TP4 | E55: TP4 | F55: TP4 | G55: TP4 | H55: TP4 | I55: TP4 | J55: TP4 | K55: TP4 | L55: TP4
B56: When TP1 Hits, Move Stop To (R) [tick box] | C56: InpMv1On | D56: Off | E56: Off | F56: Off | G56: Off | H56: Off | I56: Off | J56: Off | K56: Off | L56: Off
B57: ... value (R) [same line] | C57: InpMv1R | D57: 0 | E57: 0 | F57: 0 | G57: 0 | H57: 0 | I57: 0 | J57: 0 | K57: 0 | L57: 0
B58: When TP2 Hits, Move Stop To (R) [tick box] | C58: InpMv2On | D58: Off | E58: Off | F58: Off | G58: Off | H58: Off | I58: Off | J58: Off | K58: Off | L58: Off
B59: ... value (R) [same line] | C59: InpMv2R | D59: 0.6 | E59: 0.6 | F59: 0.6 | G59: 0.6 | H59: 0.6 | I59: 0.6 | J59: 0.6 | K59: 0.6 | L59: 0.6
B60: When TP3 Hits, Move Stop To (R) [tick box] | C60: InpMv3On | D60: Off | E60: Off | F60: Off | G60: Off | H60: Off | I60: Off | J60: Off | K60: Off | L60: Off
B61: ... value (R) [same line] | C61: InpMv3R | D61: 1 | E61: 1 | F61: 1 | G61: 1 | H61: 1 | I61: 1 | J61: 1 | K61: 1 | L61: 1
A62: ACCURACY FILTERS | B62: Don't Chase: Skip Signals Beyond [tick box] | C62: InpNoChase | D62: Off | E62: On | F62: On | G62: On | H62: On | I62: On | J62: Off | K62: On | L62: On
B63: σ From VWAP [same line] | C63: InpNoChaseSig | D63: 2.4 | E63: 2 | F63: 1.25 | G63: 2 | H63: 1.25 | I63: 1.25 | J63: 2.4 | K63: 1.25 | L63: 2.2
B64: After A Loss, No Same-Direction Trade Until A Win | C64: InpLossBlock | D64: Off | E64: Off | F64: Off | G64: Off | H64: Off | I64: Off | J64: Off | K64: Off | L64: Off
...

Sheet All profitable settings
A1: Every profitable setting found (2021-2026, after spread): profitable in 2021-23 AND 2024-26, at least 4 of 6 years positive, enough trades
A2: Use the filter arrows: e.g. Longest losing streak <= 6, or Works in = Indicator. Identical results are listed once (fewest changes). Ranked per timeframe by the weaker half.
A4: Timeframe | B4: Rank | C4: Settings to change (indicator names) | D4: Number of changes | E4: Works in | F4: Trades | G4: Trades per day | H4: Profitable trades % | I4: TP1 reached % | J4: R per trade 2021-23 | K4: R per trade 2024-26 | L4: R per trade 2021-2026 | M4: Total R after spread | N4: Years positive | O4: Longest winning streak | P4: Longest losing streak
A5: M1 | B5: 1 | C5: Stop Distance (x ATR) = 4 | Cooldown After Exit (bars) = 8 | Anchor = Month | Trade Only In Kill Zones (Indian time) = On: London Close 19:30-21:30 | D5: 4 | E5: Indicator, strategy and EA | F5: 1958 | G5: =F5/1485 -> 1.3185185 | H5: 0.3662 | I5: 0.6297 | J5: 0.0545 | K5: 0.0601 | L5: 0.0573 | M5: 112.15 | N5: 4 | O5: 8 | P5: 14
A6: M1 | B6: 2 | C6: Stop Distance (x ATR) = 4 | Cooldown After Exit (bars) = 12 | Anchor = Month | Trade Only In Kill Zones (Indian time) = On: London Close 19:30-21:30 | D6: 4 | E6: Indicator, strategy and EA | F6: 1928 | G6: =F6/1485 -> 1.2983165 | H6: 0.3646 | I6: 0.6307 | J6: 0.0498 | K6: 0.0553 | L6: 0.0526 | M6: 101.32 | N6: 5 | O6: 7 | P6: 13
A7: M1 | B7: 3 | C7: Stop Distance (x ATR) = 4 | Anchor = Month | Don't Chase: Skip Signals Beyond ... sigma From VWAP = On, 2.2 | Trade Only In Kill Zones (Indian time) = On: London Close 19:30-21:30 | D7: 4 | E7: Indicator, strategy and EA | F7: 1768 | G7: =F7/1485 -> 1.1905724 | H7: 0.3631 | I7: 0.625 | J7: 0.0481 | K7: 0.0461 | L7: 0.0471 | M7: 83.31 | N7: 5 | O7: 6 | P7: 14
A8: M1 | B8: 4 | C8: Stop Distance (x ATR) = 4 | Cooldown After Exit (bars) = 20 | Anchor = Month | Trade Only In Kill Zones (Indian time) = On: London Close 19:30-21:30 | D8: 4 | E8: Indicator, strategy and EA | F8: 1869 | G8: =F8/1485 -> 1.2585859 | H8: 0.3638 | I8: 0.6356 | J8: 0.0426 | K8: 0.0566 | L8: 0.0496 | M8: 92.62 | N8: 5 | O8: 7 | P8: 13
A9: M1 | B9: 5 | C9: Stop Distance (x ATR) = 4 | Anchor = Month | Don't Chase: Skip Signals Beyond ... sigma From VWAP = On, 2.6 | Trade Only In Kill Zones (Indian time) = On: London Close 19:30-21:30 | D9: 4 | E9: Indicator, strategy and EA | F9: 1877 | G9: =F9/1485 -> 1.2639731 | H9: 0.3612 | I9: 0.6239 | J9: 0.0475 | K9: 0.0362 | L9: 0.0418 | M9: 78.49 | N9: 4 | O9: 6 | P9: 14
A10: M1 | B10: 6 | C10: Stop Distance (x ATR) = 4 | Anchor = Month | Skip Signals Too Close To VWAP: Min Distance (x ATR) = On, 0.75 | Trade Only In Kill Zones (Indian time) = On: London Close 19:30-21:30 | D10: 4 | E10: Indicator, strategy and EA | F10: 2001 | G10: =F10/1485 -> 1.3474747 | H10: 0.3613 | I10: 0.6262 | J10: 0.0513 | K10: 0.0343 | L10: 0.0428 | M10: 85.56 | N10: 4 | O10: 8 | P10: 14
A11: M1 | B11: 7 | C11: Stop Distance (x ATR) = 4 | Anchor = Month | Trade Only In Kill Zones (Indian time) = On: London Close 19:30-21:30 | D11: 3 | E11: Indicator, strategy and EA | F11: 2006 | G11: =F11/1485 -> 1.3508418 | H11: 0.3609 | I11: 0.6261 | J11: 0.0489 | K11: 0.0341 | L11: 0.0415 | M11: 83.21 | N11: 4 | O11: 8 | P11: 14
A12: M1 | B12: 8 | C12: Stop Distance (x ATR) = 4 | Anchor = Month | Skip Choppy Sessions: Max VWAP Crosses Per 100 Bars = On, 6 | Trade Only In Kill Zones (Indian time) = On: London Close 19:30-21:30 | D12: 4 | E12: Indicator, strategy and EA | F12: 2003 | G12: =F12/1485 -> 1.3488215 | H12: 0.3615 | I12: 0.6266 | J12: 0.0522 | K12: 0.0341 | L12: 0.0431 | M12: 86.4 | N12: 4 | O12: 8 | P12: 14
A13: M1 | B13: 9 | C13: Stop Distance (x ATR) = 4 | Cooldown After Exit (bars) = 8 | Anchor = Month | Trade Only In Kill Zones (Indian time) = On: London Close 19:30-21:30 | Close % At TP1 = 30 | D13: 5 | E13: Strategy and EA only (partial close) | F13: 1958 | G13: =F13/1485 -> 1.3185185 | H13: 0.3662 | I13: 0.6297 | J13: 0.0318 | K13: 0.0281 | L13: 0.03 | M13: 58.69 | N13: 4 | O13: 8 | P13: 14
A14: M1 | B14: 10 | C14: Stop Distance (x ATR) = 4 | Cooldown After Exit (bars) = 30 | Anchor = Month | Trade Only In Kill Zones (Indian time) = On: London Close 19:30-21:30 | D14: 4 | E14: Indicator, strategy and EA | F14: 1802 | G14: =F14/1485 -> 1.213468 | H14: 0.3646 | I14: 0.626 | J14: 0.0286 | K14: 0.075 | L14: 0.0516 | M14: 93 | N14: 4 | O14: 7 | P14: 12
A15: M1 | B15: 11 | C15: Stop Distance (x ATR) = 4 | Cooldown After Exit (bars) = 12 | Anchor = Month | Trade Only In Kill Zones (Indian time) = On: London Close 19:30-21:30 | Close % At TP1 = 30 | D15: 5 | E15: Strategy and EA only (partial close) | F15: 1928 | G15: =F15/1485 -> 1.2983165 | H15: 0.3646 | I15: 0.6307 | J15: 0.0275 | K15: 0.0267 | L15: 0.0271 | M15: 52.3 | N15: 4 | O15: 7 | P15: 13
A16: M1 | B16: 12 | C16: Min Displacement Range (x ATR) = 0.4 | Stop Distance (x ATR) = 4 | Anchor = Month | Trade Only In Kill Zones (Indian time) = On: London Close 19:30-21:30 | D16: 4 | E16: Indicator, strategy and EA | F16: 2111 | G16: =F16/1485 -> 1.4215488 | H16: 0.3614 | I16: 0.6239 | J16: 0.0632 | K16: 0.0249 | L16: 0.0439 | M16: 92.74 | N16: 4 | O16: 7 | P16: 14
... A4170: H1 | B4170: 1942 | C4170: Structure Lookback (bars) = 20 | Min Displacement Range (x ATR) = 0.5 | Min Displacement Body (% of range) = 45 | Stop Distance (x ATR) = 2.2 | TP4 (R) = 3 | Anchor = Month | Don't Chase: Skip Signals Beyond ... sigma From VWAP = On, 2 | Close % At TP1 = 30 | D4170: 8 | E4170: Strategy and EA only (partial close) | F4170: 371 | G4170: =F4170/1485 -> 0.24983165 | H4170: 0.2938 | I4170: 0.6469 | J4170: 0.2179 | K4170: 0.0001 | L4170: 0.1146 | M4170: 42.5 | N4170: 5 | O4170: 3 | P4170: 13

Sheet Recovery rules
A1: All 19 loss-recovery rules of the strategy + Off, on each timeframe and setting (2021-2026, after spread)
A2: $10,000 start, $50 base risk, sized like the strategy (a stop-out loses the computed risk incl. spread), no leverage limit. "$500 cap" = Hard Cap on, Clamp. Ranked only if the account survived, made money, never risked more than $500 (5% of the start) on one trade and never fell more than 40% from a peak. Exact recovery, Oscar's Grind and Crooks divide by the R of the final target, like the strategy. Crooks with Start again, splits and random orders: sheet Crooks A and B test.
A4: SUMMARY - every rule on the 8 profitable best / low-streak settings (all timeframes)
A5: Recovery rule | B5: Hard cap | C5: Account survived (of 8) | D5: Eligible (survived, profitable, max risk <= $500, drawdown <= 40%) | E5: Average rank (1 = best) | F5: Profit / drawdown vs Off (average) | G5: Net profit vs Off (average) | H5: Verdict
A6: Off | B6: none | C6: 8 | D6: 8 | E6: 2.1 | F6: 1 | G6: 1 | H6: baseline
A7: Off | B7: $500 | C7: 8 | D7: 8 | E7: 2.1 | F7: 1 | G7: 1 | H7: baseline
A8: Crooks B | B8: $500 | C8: 8 | D8: 8 | E8: 3.4 | F8: 0.948 | G8: 1.38 | H8: about as good as Off, more profit
A9: % of equity | B9: $500 | C9: 8 | D9: 8 | E9: 5.4 | F9: 0.812 | G9: 2.89 | H9: worse risk-adjusted than Off
A10: Paroli | B10: none | C10: 8 | D10: 8 | E10: 6 | F10: 0.806 | G10: 1.79 | H10: worse risk-adjusted than Off
A11: Paroli | B11: $500 | C11: 8 | D11: 8 | E11: 6 | F11: 0.806 | G11: 1.79 | H11: worse risk-adjusted than Off
A12: % of equity | B12: none | C12: 8 | D12: 7 | E12: 5.4 | F12: 0.807 | G12: 2.6 | H12: worse risk-adjusted than Off
A13: Crooks B | B13: none | C13: 8 | D13: 6 | E13: 3.3 | F13: 1.008 | G13: 1.27 | H13: about as good as Off, more profit
A14: Rule C: carry the losses | B14: $500 | C14: 7 | D14: 6 | E14: 5 | F14: 0.944 | G14: 2.25 | H14: about as good as Off, more profit
A15: Crooks A | B15: $500 | C15: 8 | D15: 6 | E15: 6.2 | F15: 0.691 | G15: 1.31 | H15: much worse than Off
A16: Oscar's Grind | B16: $500 | C16: 8 | D16: 5 | E16: 8.8 | F16: 0.728 | G16: 2.53 | H16: worse risk-adjusted than Off
A17: Reverse D'Alembert | B17: $500 | C17: 8 | D17: 4 | E17: 4.5 | F17: 0.921 | G17: 4.99 | H17: about as good as Off, more profit
... A40: Exact recovery at final TP | B40: none | C40: 4 | D40: 1 | E40: 14 | F40: 0.705 | G40: 1.61 | H40: worse risk-adjusted than Off
A41: Rules that were never eligible (blew the account, needed more than $500 on one trade or fell more than 40% in every case) are not listed. Detail per timeframe below.
A43: Timeframe | B43: Settings | C43: Recovery rule | D43: Rule detail | E43: Hard cap | F43: Net profit ($) | G43: Max drawdown ($) | H43: Max drawdown % | I43: Largest risk on one trade ($) | J43: Account blown? | K43: Profit / max drawdown | L43: Profit factor | M43: Worst run of losing trades ($) | N43: Rank (survived, by profit / drawdown)
A44: M1 | B44: Default settings | C44: Off | D44: fixed $50 risk | E44: none | F44: -10035.04 | G44: 10184.86 | H44: 1.0035 | I44: 50 | J44: YES, after 482 trades | K44: =IF(G44=0,"",F44/G44) -> -0.98528993 | L44: 0.43 | M44: 800 | N44: -
A45: M1 | B45: Default settings | C45: Off | D45: fixed $50 risk | E45: $500 | F45: -10035.04 | G45: 10184.86 | H45: 1.0035 | I45: 50 | J45: YES, after 482 trades | K45: =IF(G45=0,"",F45/G45) -> -0.98528993 | L45: 0.43 | M45: 800 | N45: -
A46: M1 | B46: Default settings | C46: Recover all losses on the next trade | D46: risk = $50 + all open losses | E46: none | F46: -10147.44 | G46: 12750 | H46: 1.0117 | I46: 6400 | J46: YES, after 35 trades | K46: =IF(G46=0,"",F46/G46) -> -0.79587765 | L46: 0.432 | M46: 12750 | N46: -
A47: M1 | B47: Default settings | C47: Recover all losses on the next trade | D47: risk = $50 + all open losses | E47: $500 | F47: -10237.77 | G47: 10715.68 | H47: 1.0227 | I47: 500 | J47: YES, after 48 trades | K47: =IF(G47=0,"",F47/G47) -> -0.95540087 | L47: 0.346 | M47: 5000 | N47: -
A48: M1 | B48: Default settings | C48: Recover losses over N trades | D48: N = 3 | E48: none | F48: -10095.38 | G48: 10315.54 | H48: 1.0093 | I48: 2616.39 | J48: YES, after 36 trades | K48: =IF(G48=0,"",F48/G48) -> -0.97865744 | L48: 0.21 | M48: 9679.74 | N48: -
A49: M1 | B49: Default settings | C49: Recover losses over N trades | D49: N = 3 | E49: $500 | F49: -10168.81 | G49: 10388.98 | H49: 1.0165 | I49: 500 | J49: YES, after 57 trades | K49: =IF(G49=0,"",F49/G49) -> -0.97880735 | L49: 0.34 | M49: 4802.46 | N49: -
A50: M1 | B50: Default settings | C50: Recover a % of losses per trade | D50: 50% of open losses | E50: none | F50: -10064.5 | G50: 10315.47 | H50: 1.0063 | I50: 3471.82 | J50: YES, after 37 trades | K50: =IF(G50=0,"",F50/G50) -> -0.97567052 | L50: 0.262 | M50: 10234.85 | N50: -
A51: M1 | B51: Default settings | C51: Recover a % of losses per trade | D51: 50% of open losses | E51: $500 | F51: -10061.26 | G51: 10312.23 | H51: 1.006 | I51: 500 | J51: YES, after 55 trades | K51: =IF(G51=0,"",F51/G51) -> -0.97566288 | L51: 0.36 | M51: 4962.48 | N51: -
A52: M1 | B52: Default settings | C52: Martingale (multiply after each loss) | D52: x2 after each loss | E52: none | F52: -10147.44 | G52: 12750 | H52: 1.0117 | I52: 6400 | J52: YES, after 35 trades | K52: =IF(G52=0,"",F52/G52) -> -0.79587765 | L52: 0.432 | M52: 12750 | N52: -
A53: M1 | B53: Default settings | C53: Martingale (multiply after each loss) | D53: x2 after each loss | E53: $500 | F53: -10237.77 | G53: 10715.68 | H53: 1.0227 | I53: 500 | J53: YES, after 48 trades | K53: =IF(G53=0,"",F53/G53) -> -0.95540087 | L53: 0.346 | M53: 5000 | N53: -
A54: M1 | B54: Default settings | C54: Exact recovery at final TP | D54: sized so the final TP repays open losses | E54: none | F54: -10064.5 | G54: 10315.47 | H54: 1.0063 | I54: 3471.82 | J54: YES, after 37 trades | K54: =IF(G54=0,"",F54/G54) -> -0.97567052 | L54: 0.262 | M54: 10234.85 | N54: -
A55: M1 | B55: Default settings | C55: Exact recovery at final TP | D55: sized so the final TP repays open losses | E55: $500 | F55: -10061.26 | G55: 10312.23 | H55: 1.006 | I55: 500 | J55: YES, after 55 trades | K55: =IF(G55=0,"",F55/G55) -> -0.97566288 | L55: 0.36 | M55: 4962.48 | N55: -
... A83: M1 | B83: Default settings | C83: Crooks B | D83: as Crooks A, recovery = loss / 3 / final TP R; resets when all is won back | E83: $500 | F83: -10127.2 | G83: 10277.03 | H83: 1.0125 | I83: 500 | J83: YES, after 230 trades | K83: =IF(G83=0,"",F83/G83) -> -0.98542089 | L83: 0.627 | M83: 2380 | N83: -
A85: M1 | B85: Best settings (profit) | C85: Off | D85: fixed $50 risk | E85: none | F85: 5441.57 | G85: 1480.81 | H85: 0.1332 | I85: 50 | J85: no | K85: =IF(G85=0,"",F85/G85) -> 3.6747253 | L85: 1.088 | M85: 700 | N85: 2
A86: M1 | B86: Best settings (profit) | C86: Off | D86: fixed $50 risk | E86: $500 | F86: 5441.57 | G86: 1480.81 | H86: 0.1332 | I86: 50 | J86: no | K86: =IF(G86=0,"",F86/G86) -> 3.6747253 | L86: 1.088 | M86: 700 | N86: 2
A87: M1 | B87: Best settings (profit) | C87: Recover all losses on the next trade | D87: risk = $50 + all open losses | E87: none | F87: -28959.9 | G87: 51150 | H87: 1.589 | I87: 25600 | J87: YES, after 162 trades | K87: =IF(G87=0,"",F87/G87) -> -0.56617595 | L87: 0.599 | M87: 51150 | N87: -
A88: M1 | B88: Best settings (profit) | C88: Recover all losses on the next trade | D88: risk = $50 + all open losses | E88: $500 | F88: 52339.87 | G88: 13558.1 | H88: 0.4959 | I88: 500 | J88: no | K88: =IF(G88=0,"",F88/G88) -> 3.8604133 | L88: 1.116 | M88: 7000 | N88: -
A89: M1 | B89: Best settings (profit) | C89: Recover losses over N trades | D89: N = 3 | E89: none | F89: 36461.3 | G89: 14332.43 | H89: 0.5516 | I89: 4827.48 | J89: no | K89: =IF(G89=0,"",F89/G89) -> 2.543972 | L89: 1.193 | M89: 14224.38 | N89: -
A90: M1 | B90: Best settings (profit) | C90: Recover losses over N trades | D90: N = 3 | E90: $500 | F90: 29934.97 | G90: 8712.49 | H90: 0.3639 | I90: 500 | J90: no | K90: =IF(G90=0,"",F90/G90) -> 3.4358685 | L90: 1.128 | M90: 5777.5 | N90: 4
A91: M1 | B91: Best settings (profit) | C91: Recover a % of losses per trade | D91: 50% of open losses | E91: none | F91: 59799.66 | G91: 29092.93 | H91: 0.595 | I91: 14596.46 | J91: no | K91: =IF(G91=0,"",F91/G91) -> 2.0554705 | L91: 1.276 | M91: 29092.93 | N91: -
A92: M1 | B92: Best settings (profit) | C92: Recover a % of losses per trade | D92: 50% of open losses | E92: $500 | F92: 38963.44 | G92: 12674.16 | H92: 0.3948 | I92: 500 | J92: no | K92: =IF(G92=0,"",F92/G92) -> 3.0742424 | L92: 1.127 | M92: 5888.39 | N92: 7
...

Sheet Rule C split test
A1: Rule C and Rule C split with the loss split over 1, 2, 3, 4 or 5 trades (2021-2026, after spread)
A2: Rule C: carried = how far closed equity is below its last high; next risk = max(base, carried / split). Rule C split: the same, and the base steps up with total profit (200 -> 200/3, 500 -> 500/5, 1000 -> 1000/8, then +1 part per +500). $10,000 start, $50 base, hard cap $500 with Clamp unless shown. Partial closes update the carried losses per part.
A4: WHAT IT SHOWS
A5: 1. With the best settings (profitable signals) and the hard cap on, Rule C split at split 2 or 3 made 5-9x the profit of fixed risk (Off), and per $ staked it lost about the same as Off.
A6: 2. Without the hard cap, Rule C split at split 1-3 blew the $10,000 account on M1, M5 and M15. With the default settings every Rule C variant blew the account.
A7: 3. Split 3 was the better choice than 2 on most cases: similar profit with a smaller drawdown (M15 best: 33% vs 46%). Drawdowns are still far larger than Off (16-70% vs 3-17%).
A8: 4. The cap action matters: "Start again" (forget the carried losses when the risk would pass the cap) kept M5 alive where Clamp blew it, and gave M15 its best profit for the drawdown.
A9: 5. Stress test (part 3): add 0.05-0.10 R of extra cost per trade (live slippage, weaker edge). H1 stays clearly profitable; M15 holds to about 0.05 R; M1 and M5 blow up - their edge is too thin.
A11: PART 1 - split 1 to 5, without and with the $500 hard cap (Clamp)
A12: Timeframe | B12: Settings | C12: Rule | D12: Split | E12: Hard cap | F12: Net profit ($) | G12: Max drawdown ($) | H12: Max drawdown % | I12: Average stake ($) | J12: Largest stake ($) | K12: Account blown? | L12: Profit / max drawdown | M12: vs Off (1 = same) | N12: Profit per $ of average stake | O12: Max drawdown per $ of average stake | P12: 2021-23 alone: net ($) | Q12: 2024-26 alone: net ($)
A13: M1 | B13: Default settings | C13: Off (fixed $50) | D13: - | E13: - | F13: -10035.04 | G13: 10184.86 | H13: 1.0035 | I13: 50 | J13: 50 | K13: YES, after 482 trades | L13: =IF(G13=0,"",F13/G13) -> -0.98528993 | M13: 1 | N13: =IF(I13=0,"",F13/I13) -> -200.7008 | O13: =IF(I13=0,"",G13/I13) -> 203.6972 | P13: BLOWN | Q13: BLOWN
A14: M1 | B14: Default settings | C14: Rule C | D14: 1 | E14: none | F14: -11542.87 | G14: 12800 | H14: 1.1371 | I14: 495.95 | J14: 6400 | K14: YES, after 36 trades | L14: =IF(G14=0,"",F14/G14) -> -0.90178672 | M14: =IF(OR(L13="",L13<=0,L14=""),"",L14/L13) | N14: =IF(I14=0,"",F14/I14) -> -23.274262 | O14: =IF(I14=0,"",G14/I14) -> 25.809053 | P14: BLOWN | Q14: BLOWN
A15: M1 | B15: Default settings | C15: Rule C | D15: 1 | E15: $500 | F15: -10372.82 | G15: 10667.63 | H15: 1.0362 | I15: 387.04 | J15: 500 | K15: YES, after 49 trades | L15: =IF(G15=0,"",F15/G15) -> -0.97236406 | M15: =IF(OR(L13="",L13<=0,L15=""),"",L15/L13) | N15: =IF(I15=0,"",F15/I15) -> -26.800382 | O15: =IF(I15=0,"",G15/I15) -> 27.562087 | P15: BLOWN | Q15: BLOWN
A16: M1 | B16: Default settings | C16: Rule C | D16: 2 | E16: none | F16: -12357.22 | G16: 12531.92 | H16: 1.2317 | I16: 493.42 | J16: 4177.31 | K16: YES, after 42 trades | L16: =IF(G16=0,"",F16/G16) -> -0.9860596 | M16: =IF(OR(L13="",L13<=0,L16=""),"",L16/L13) | N16: =IF(I16=0,"",F16/I16) -> -25.044019 | O16: =IF(I16=0,"",G16/I16) -> 25.398079 | P16: BLOWN | Q16: BLOWN
A17: M1 | B17: Default settings | C17: Rule C | D17: 2 | E17: $500 | F17: -10102.43 | G17: 10277.13 | H17: 1.0101 | I17: 317.1 | J17: 500 | K17: YES, after 70 trades | L17: =IF(G17=0,"",F17/G17) -> -0.98300109 | M17: =IF(OR(L13="",L13<=0,L17=""),"",L17/L13) | N17: =IF(I17=0,"",F17/I17) -> -31.858814 | O17: =IF(I17=0,"",G17/I17) -> 32.409745 | P17: BLOWN | Q17: BLOWN
A18: M1 | B18: Default settings | C18: Rule C | D18: 3 | E18: none | F18: -12514.58 | G18: 12664.41 | H18: 1.2477 | I18: 446.12 | J18: 3166.1 | K18: YES, after 42 trades | L18: =IF(G18=0,"",F18/G18) -> -0.98816921 | M18: =IF(OR(L13="",L13<=0,L18=""),"",L18/L13) | N18: =IF(I18=0,"",F18/I18) -> -28.052049 | O18: =IF(I18=0,"",G18/I18) -> 28.3879 | P18: BLOWN | Q18: BLOWN
A19: M1 | B19: Default settings | C19: Rule C | D19: 3 | E19: $500 | F19: -10456.31 | G19: 10606.13 | H19: 1.045 | I19: 298.43 | J19: 500 | K19: YES, after 63 trades | L19: =IF(G19=0,"",F19/G19) -> -0.98587421 | M19: =IF(OR(L13="",L13<=0,L19=""),"",L19/L13) | N19: =IF(I19=0,"",F19/I19) -> -35.037731 | O19: =IF(I19=0,"",G19/I19) -> 35.539758 | P19: BLOWN | Q19: BLOWN
A20: M1 | B20: Default settings | C20: Rule C | D20: 4 | E20: none | F20: -10778.99 | G20: 10928.82 | H20: 1.0767 | I20: 415.27 | J20: 2185.76 | K20: YES, after 49 trades | L20: =IF(G20=0,"",F20/G20) -> -0.98629038 | M20: =IF(OR(L13="",L13<=0,L20=""),"",L20/L13) | N20: =IF(I20=0,"",F20/I20) -> -25.956582 | O20: =IF(I20=0,"",G20/I20) -> 26.317384 | P20: BLOWN | Q20: BLOWN
A21: M1 | B21: Default settings | C21: Rule C | D21: 4 | E21: $500 | F21: -10066.81 | G21: 10216.63 | H21: 1.0066 | I21: 294.45 | J21: 500 | K21: YES, after 67 trades | L21: =IF(G21=0,"",F21/G21) -> -0.98533567 | M21: =IF(OR(L13="",L13<=0,L21=""),"",L21/L13) | N21: =IF(I21=0,"",F21/I21) -> -34.188521 | O21: =IF(I21=0,"",G21/I21) -> 34.697334 | P21: BLOWN | Q21: BLOWN
A22: M1 | B22: Default settings | C22: Rule C | D22: 5 | E22: none | F22: -10831.28 | G22: 10981.1 | H22: 1.0819 | I22: 387.62 | J22: 1896.58 | K22: YES, after 55 trades | L22: =IF(G22=0,"",F22/G22) -> -0.98635656 | M22: =IF(OR(L13="",L13<=0,L22=""),"",L22/L13) | N22: =IF(I22=0,"",F22/I22) -> -27.943037 | O22: =IF(I22=0,"",G22/I22) -> 28.32955 | P22: BLOWN | Q22: BLOWN
A23: M1 | B23: Default settings | C23: Rule C | D23: 5 | E23: $500 | F23: -10165.7 | G23: 10315.53 | H23: 1.0163 | I23: 290.36 | J23: 500 | K23: YES, after 71 trades | L23: =IF(G23=0,"",F23/G23) -> -0.9854753 | M23: =IF(OR(L13="",L13<=0,L23=""),"",L23/L13) | N23: =IF(I23=0,"",F23/I23) -> -35.010676 | O23: =IF(I23=0,"",G23/I23) -> 35.526691 | P23: BLOWN | Q23: BLOWN
A24: M1 | B24: Default settings | C24: Rule C split | D24: 1 | E24: none | F24: -10718.14 | G24: 12800 | H24: 1.0594 | I24: 628.1 | J24: 6400 | K24: YES, after 34 trades | L24: =IF(G24=0,"",F24/G24) -> -0.83735469 | M24: =IF(OR(L13="",L13<=0,L24=""),"",L24/L13) | N24: =IF(I24=0,"",F24/I24) -> -17.064385 | O24: =IF(I24=0,"",G24/I24) -> 20.378921 | P24: BLOWN | Q24: BLOWN
A25: M1 | B25: Default settings | C25: Rule C split | D25: 1 | E25: $500 | F25: -10179.94 | G25: 10499.01 | H25: 1.0174 | I25: 391.84 | J25: 500 | K25: YES, after 48 trades | L25: =IF(G25=0,"",F25/G25) -> -0.96960952 | M25: =IF(OR(L13="",L13<=0,L25=""),"",L25/L13) | N25: =IF(I25=0,"",F25/I25) -> -25.979839 | O25: =IF(I25=0,"",G25/I25) -> 26.794125 | P25: BLOWN | Q25: BLOWN
A26: M1 | B26: Default settings | C26: Rule C split | D26: 2 | E26: none | F26: -12357.22 | G26: 12531.92 | H26: 1.2317 | I26: 493.42 | J26: 4177.31 | K26: YES, after 42 trades | L26: =IF(G26=0,"",F26/G26) -> -0.9860596 | M26: =IF(OR(L13="",L13<=0,L26=""),"",L26/L13) | N26: =IF(I26=0,"",F26/I26) -> -25.044019 | O26: =IF(I26=0,"",G26/I26) -> 25.398079 | P26: BLOWN | Q26: BLOWN
A27: M1 | B27: Default settings | C27: Rule C split | D27: 2 | E27: $500 | F27: -10102.43 | G27: 10277.13 | H27: 1.0101 | I27: 317.1 | J27: 500 | K27: YES, after 70 trades | L27: =IF(G27=0,"",F27/G27) -> -0.98300109 | M27: =IF(OR(L13="",L13<=0,L27=""),"",L27/L13) | N27: =IF(I27=0,"",F27/I27) -> -31.858814 | O27: =IF(I27=0,"",G27/I27) -> 32.409745 | P27: BLOWN | Q27: BLOWN
A28: M1 | B28: Default settings | C28: Rule C split | D28: 3 | E28: none | F28: -12514.58 | G28: 12664.41 | H28: 1.2477 | I28: 446.12 | J28: 3166.1 | K28: YES, after 42 trades | L28: =IF(G28=0,"",F28/G28) -> -0.98816921 | M28: =IF(OR(L13="",L13<=0,L28=""),"",L28/L13) | N28: =IF(I28=0,"",F28/I28) -> -28.052049 | O28: =IF(I28=0,"",G28/I28) -> 28.3879 | P28: BLOWN | Q28: BLOWN
A29: M1 | B29: Default settings | C29: Rule C split | D29: 3 | E29: $500 | F29: -10456.31 | G29: 10606.13 | H29: 1.045 | I29: 298.43 | J29: 500 | K29: YES, after 63 trades | L29: =IF(G29=0,"",F29/G29) -> -0.98587421 | M29: =IF(OR(L13="",L13<=0,L29=""),"",L29/L13) | N29: =IF(I29=0,"",F29/I29) -> -35.037731 | O29: =IF(I29=0,"",G29/I29) -> 35.539758 | P29: BLOWN | Q29: BLOWN
A30: M1 | B30: Default settings | C30: Rule C split | D30: 4 | E30: none | F30: -10778.99 | G30: 10928.82 | H30: 1.0767 | I30: 415.27 | J30: 2185.76 | K30: YES, after 49 trades | L30: =IF(G30=0,"",F30/G30) -> -0.98629038 | M30: =IF(OR(L13="",L13<=0,L30=""),"",L30/L13) | N30: =IF(I30=0,"",F30/I30) -> -25.956582 | O30: =IF(I30=0,"",G30/I30) -> 26.317384 | P30: BLOWN | Q30: BLOWN
A31: M1 | B31: Default settings | C31: Rule C split | D31: 4 | E31: $500 | F31: -10066.81 | G31: 10216.63 | H31: 1.0066 | I31: 294.45 | J31: 500 | K31: YES, after 67 trades | L31: =IF(G31=0,"",F31/G31) -> -0.98533567 | M31: =IF(OR(L13="",L13<=0,L31=""),"",L31/L13) | N31: =IF(I31=0,"",F31/I31) -> -34.188521 | O31: =IF(I31=0,"",G31/I31) -> 34.697334 | P31: BLOWN | Q31: BLOWN
